TypeError: 'tuple' object is not callable

![image](https://user-images.githubusercontent.com/89775352/164449430-f6bf69dc-79ab-4b2d-a264-ebba6385c799.png)


흔하게 저지를 수 있는 실수, 이 에러는 괄호나 쉼표를 잘못 붙여 주었을 때 자주 나타난다. 

예를 들어 df. shape() 괄호 붙이면 이 에러가 나온다. 이 상황에선 붙일 필요 없다!  
